<?xml version="1.0" ?>
<testsuite name="TestRoutes.TestUsersBlueprint-20240410221946" tests="1" time="0.037" failures="0" errors="1">
	<testcase classname="TestRoutes.TestUsersBlueprint" name="test_login" time="0.037">
		<error type="JSONDecodeError" message="Expecting value: line 1 column 1 (char 0)"><![CDATA[Traceback (most recent call last):
  File "C:\Program Files\WindowsApps\PythonSoftwareFoundation.Python.3.11_3.11.2544.0_x64__qbz5n2kfra8p0\Lib\unittest\mock.py", line 1378, in patched
    return func(*newargs, **newkeywargs)
           ^^^^^^^^^^^^^^^^^^^^^^^^^^^^^
  File "C:\Users\Omistaja\PycharmProjects\MLEngine3\backend\tests\TestRoutes.py", line 29, in test_login
    data = json.loads(response.data.decode())
           ^^^^^^^^^^^^^^^^^^^^^^^^^^^^^^^^^^
  File "C:\Program Files\WindowsApps\PythonSoftwareFoundation.Python.3.11_3.11.2544.0_x64__qbz5n2kfra8p0\Lib\json\__init__.py", line 346, in loads
    return _default_decoder.decode(s)
           ^^^^^^^^^^^^^^^^^^^^^^^^^^
  File "C:\Program Files\WindowsApps\PythonSoftwareFoundation.Python.3.11_3.11.2544.0_x64__qbz5n2kfra8p0\Lib\json\decoder.py", line 337, in decode
    obj, end = self.raw_decode(s, idx=_w(s, 0).end())
               ^^^^^^^^^^^^^^^^^^^^^^^^^^^^^^^^^^^^^^
  File "C:\Program Files\WindowsApps\PythonSoftwareFoundation.Python.3.11_3.11.2544.0_x64__qbz5n2kfra8p0\Lib\json\decoder.py", line 355, in raw_decode
    raise JSONDecodeError("Expecting value", s, err.value) from None
json.decoder.JSONDecodeError: Expecting value: line 1 column 1 (char 0)
]]></error>
	</testcase>
	<system-out><![CDATA[]]></system-out>
	<system-err><![CDATA[[2024-04-10 22:19:46,935] ERROR in app: Exception on /login [POST]
Traceback (most recent call last):
  File "C:\Users\Omistaja\PycharmProjects\MLEngine3\.venv\Lib\site-packages\flask\app.py", line 1463, in wsgi_app
    response = self.full_dispatch_request()
               ^^^^^^^^^^^^^^^^^^^^^^^^^^^^
  File "C:\Users\Omistaja\PycharmProjects\MLEngine3\.venv\Lib\site-packages\flask\app.py", line 872, in full_dispatch_request
    rv = self.handle_user_exception(e)
         ^^^^^^^^^^^^^^^^^^^^^^^^^^^^^
  File "C:\Users\Omistaja\PycharmProjects\MLEngine3\.venv\Lib\site-packages\flask\app.py", line 870, in full_dispatch_request
    rv = self.dispatch_request()
         ^^^^^^^^^^^^^^^^^^^^^^^
  File "C:\Users\Omistaja\PycharmProjects\MLEngine3\.venv\Lib\site-packages\flask\app.py", line 855, in dispatch_request
    return self.ensure_sync(self.view_functions[rule.endpoint])(**view_args)  # type: ignore[no-any-return]
           ^^^^^^^^^^^^^^^^^^^^^^^^^^^^^^^^^^^^^^^^^^^^^^^^^^^^^^^^^^^^^^^^^
  File "C:\Users\Omistaja\PycharmProjects\MLEngine3\backend\routes.py", line 15, in login
    user = login_user(credentials)
           ^^^^^^^^^^^^^^^^^^^^^^^
  File "C:\Users\Omistaja\PycharmProjects\MLEngine3\backend\services.py", line 49, in login_user
    user = User.query.filter_by(email=email, password=password).first()
           ^^^^^^^^^^^^^^^^^^^^^^^^^^^^^^^^^^^^^^^^^^^^^^^^^^^^^^^^^^^^
  File "C:\Users\Omistaja\PycharmProjects\MLEngine3\.venv\Lib\site-packages\sqlalchemy\orm\query.py", line 2728, in first
    return self.limit(1)._iter().first()  # type: ignore
           ^^^^^^^^^^^^^^^^^^^^^
  File "C:\Users\Omistaja\PycharmProjects\MLEngine3\.venv\Lib\site-packages\sqlalchemy\orm\query.py", line 2827, in _iter
    result: Union[ScalarResult[_T], Result[_T]] = self.session.execute(
                                                  ^^^^^^^^^^^^^^^^^^^^^
  File "C:\Users\Omistaja\PycharmProjects\MLEngine3\.venv\Lib\site-packages\sqlalchemy\orm\session.py", line 2306, in execute
    return self._execute_internal(
           ^^^^^^^^^^^^^^^^^^^^^^^
  File "C:\Users\Omistaja\PycharmProjects\MLEngine3\.venv\Lib\site-packages\sqlalchemy\orm\session.py", line 2179, in _execute_internal
    bind = self.get_bind(**bind_arguments)
           ^^^^^^^^^^^^^^^^^^^^^^^^^^^^^^^
  File "C:\Users\Omistaja\PycharmProjects\MLEngine3\.venv\Lib\site-packages\flask_sqlalchemy\session.py", line 53, in get_bind
    engines = self._db.engines
              ^^^^^^^^^^^^^^^^
  File "C:\Users\Omistaja\PycharmProjects\MLEngine3\.venv\Lib\site-packages\flask_sqlalchemy\extension.py", line 690, in engines
    raise RuntimeError(
RuntimeError: The current Flask app is not registered with this 'SQLAlchemy' instance. Did you forget to call 'init_app', or did you create multiple 'SQLAlchemy' instances?
]]></system-err>
</testsuite>
