<?xml version="1.0" ?>
<testsuite name="TestModelPrediction.TestModelPredictions-20240426134646" tests="1" time="0.018" failures="0" errors="1">
	<testcase classname="TestModelPrediction.TestModelPredictions" name="test_prediction_shape" time="0.018">
		<error type="FileNotFoundError" message="[Errno 2] No such file or directory: 'best_model45.pth'"><![CDATA[Traceback (most recent call last):
  File "C:\Users\Omistaja\PycharmProjects\MLEngine3\backend\tests\TestModelPrediction.py", line 12, in setUp
    self.model.load_state_dict(torch.load('best_model45.pth'))
                               ^^^^^^^^^^^^^^^^^^^^^^^^^^^^^^
  File "C:\Users\Omistaja\PycharmProjects\MLEngine3\.venv\Lib\site-packages\torch\serialization.py", line 998, in load
    with _open_file_like(f, 'rb') as opened_file:
         ^^^^^^^^^^^^^^^^^^^^^^^^
  File "C:\Users\Omistaja\PycharmProjects\MLEngine3\.venv\Lib\site-packages\torch\serialization.py", line 445, in _open_file_like
    return _open_file(name_or_buffer, mode)
           ^^^^^^^^^^^^^^^^^^^^^^^^^^^^^^^^
  File "C:\Users\Omistaja\PycharmProjects\MLEngine3\.venv\Lib\site-packages\torch\serialization.py", line 426, in __init__
    super().__init__(open(name, mode))
                     ^^^^^^^^^^^^^^^^
FileNotFoundError: [Errno 2] No such file or directory: 'best_model45.pth'
]]></error>
	</testcase>
	<system-out><![CDATA[]]></system-out>
	<system-err><![CDATA[]]></system-err>
</testsuite>
