<?xml version="1.0" ?>
<testsuite name="TestRoutes.TestUsersBlueprint-20240410221408" tests="5" time="0.147" failures="0" errors="5">
	<testcase classname="TestRoutes.TestUsersBlueprint" name="test_login" time="0.120">
		<error type="AttributeError" message="&lt;module 'app2' from 'C:\\Users\\Omistaja\\PycharmProjects\\MLEngine3\\backend\\app2.py'&gt; does not have the attribute 'login_user'"><![CDATA[Traceback (most recent call last):
  File "C:\Program Files\WindowsApps\PythonSoftwareFoundation.Python.3.11_3.11.2544.0_x64__qbz5n2kfra8p0\Lib\unittest\mock.py", line 1375, in patched
    with self.decoration_helper(patched,
  File "C:\Program Files\WindowsApps\PythonSoftwareFoundation.Python.3.11_3.11.2544.0_x64__qbz5n2kfra8p0\Lib\contextlib.py", line 137, in __enter__
    return next(self.gen)
           ^^^^^^^^^^^^^^
  File "C:\Program Files\WindowsApps\PythonSoftwareFoundation.Python.3.11_3.11.2544.0_x64__qbz5n2kfra8p0\Lib\unittest\mock.py", line 1357, in decoration_helper
    arg = exit_stack.enter_context(patching)
          ^^^^^^^^^^^^^^^^^^^^^^^^^^^^^^^^^^
  File "C:\Program Files\WindowsApps\PythonSoftwareFoundation.Python.3.11_3.11.2544.0_x64__qbz5n2kfra8p0\Lib\contextlib.py", line 517, in enter_context
    result = _enter(cm)
             ^^^^^^^^^^
  File "C:\Program Files\WindowsApps\PythonSoftwareFoundation.Python.3.11_3.11.2544.0_x64__qbz5n2kfra8p0\Lib\unittest\mock.py", line 1446, in __enter__
    original, local = self.get_original()
                      ^^^^^^^^^^^^^^^^^^^
  File "C:\Program Files\WindowsApps\PythonSoftwareFoundation.Python.3.11_3.11.2544.0_x64__qbz5n2kfra8p0\Lib\unittest\mock.py", line 1419, in get_original
    raise AttributeError(
AttributeError: <module 'app2' from 'C:\\Users\\Omistaja\\PycharmProjects\\MLEngine3\\backend\\app2.py'> does not have the attribute 'login_user'
]]></error>
	</testcase>
	<testcase classname="TestRoutes.TestUsersBlueprint" name="test_login_fail" time="0.009">
		<error type="AttributeError" message="&lt;module 'app2' from 'C:\\Users\\Omistaja\\PycharmProjects\\MLEngine3\\backend\\app2.py'&gt; does not have the attribute 'login_user'"><![CDATA[Traceback (most recent call last):
  File "C:\Program Files\WindowsApps\PythonSoftwareFoundation.Python.3.11_3.11.2544.0_x64__qbz5n2kfra8p0\Lib\unittest\mock.py", line 1375, in patched
    with self.decoration_helper(patched,
  File "C:\Program Files\WindowsApps\PythonSoftwareFoundation.Python.3.11_3.11.2544.0_x64__qbz5n2kfra8p0\Lib\contextlib.py", line 137, in __enter__
    return next(self.gen)
           ^^^^^^^^^^^^^^
  File "C:\Program Files\WindowsApps\PythonSoftwareFoundation.Python.3.11_3.11.2544.0_x64__qbz5n2kfra8p0\Lib\unittest\mock.py", line 1357, in decoration_helper
    arg = exit_stack.enter_context(patching)
          ^^^^^^^^^^^^^^^^^^^^^^^^^^^^^^^^^^
  File "C:\Program Files\WindowsApps\PythonSoftwareFoundation.Python.3.11_3.11.2544.0_x64__qbz5n2kfra8p0\Lib\contextlib.py", line 517, in enter_context
    result = _enter(cm)
             ^^^^^^^^^^
  File "C:\Program Files\WindowsApps\PythonSoftwareFoundation.Python.3.11_3.11.2544.0_x64__qbz5n2kfra8p0\Lib\unittest\mock.py", line 1446, in __enter__
    original, local = self.get_original()
                      ^^^^^^^^^^^^^^^^^^^
  File "C:\Program Files\WindowsApps\PythonSoftwareFoundation.Python.3.11_3.11.2544.0_x64__qbz5n2kfra8p0\Lib\unittest\mock.py", line 1419, in get_original
    raise AttributeError(
AttributeError: <module 'app2' from 'C:\\Users\\Omistaja\\PycharmProjects\\MLEngine3\\backend\\app2.py'> does not have the attribute 'login_user'
]]></error>
	</testcase>
	<testcase classname="TestRoutes.TestUsersBlueprint" name="test_prediction" time="0.006">
		<error type="AttributeError" message="&lt;module 'app2' from 'C:\\Users\\Omistaja\\PycharmProjects\\MLEngine3\\backend\\app2.py'&gt; does not have the attribute 'predict'"><![CDATA[Traceback (most recent call last):
  File "C:\Program Files\WindowsApps\PythonSoftwareFoundation.Python.3.11_3.11.2544.0_x64__qbz5n2kfra8p0\Lib\unittest\mock.py", line 1375, in patched
    with self.decoration_helper(patched,
  File "C:\Program Files\WindowsApps\PythonSoftwareFoundation.Python.3.11_3.11.2544.0_x64__qbz5n2kfra8p0\Lib\contextlib.py", line 137, in __enter__
    return next(self.gen)
           ^^^^^^^^^^^^^^
  File "C:\Program Files\WindowsApps\PythonSoftwareFoundation.Python.3.11_3.11.2544.0_x64__qbz5n2kfra8p0\Lib\unittest\mock.py", line 1357, in decoration_helper
    arg = exit_stack.enter_context(patching)
          ^^^^^^^^^^^^^^^^^^^^^^^^^^^^^^^^^^
  File "C:\Program Files\WindowsApps\PythonSoftwareFoundation.Python.3.11_3.11.2544.0_x64__qbz5n2kfra8p0\Lib\contextlib.py", line 517, in enter_context
    result = _enter(cm)
             ^^^^^^^^^^
  File "C:\Program Files\WindowsApps\PythonSoftwareFoundation.Python.3.11_3.11.2544.0_x64__qbz5n2kfra8p0\Lib\unittest\mock.py", line 1446, in __enter__
    original, local = self.get_original()
                      ^^^^^^^^^^^^^^^^^^^
  File "C:\Program Files\WindowsApps\PythonSoftwareFoundation.Python.3.11_3.11.2544.0_x64__qbz5n2kfra8p0\Lib\unittest\mock.py", line 1419, in get_original
    raise AttributeError(
AttributeError: <module 'app2' from 'C:\\Users\\Omistaja\\PycharmProjects\\MLEngine3\\backend\\app2.py'> does not have the attribute 'predict'
]]></error>
	</testcase>
	<testcase classname="TestRoutes.TestUsersBlueprint" name="test_register" time="0.008">
		<error type="AttributeError" message="&lt;module 'app2' from 'C:\\Users\\Omistaja\\PycharmProjects\\MLEngine3\\backend\\app2.py'&gt; does not have the attribute 'register_user'"><![CDATA[Traceback (most recent call last):
  File "C:\Program Files\WindowsApps\PythonSoftwareFoundation.Python.3.11_3.11.2544.0_x64__qbz5n2kfra8p0\Lib\unittest\mock.py", line 1375, in patched
    with self.decoration_helper(patched,
  File "C:\Program Files\WindowsApps\PythonSoftwareFoundation.Python.3.11_3.11.2544.0_x64__qbz5n2kfra8p0\Lib\contextlib.py", line 137, in __enter__
    return next(self.gen)
           ^^^^^^^^^^^^^^
  File "C:\Program Files\WindowsApps\PythonSoftwareFoundation.Python.3.11_3.11.2544.0_x64__qbz5n2kfra8p0\Lib\unittest\mock.py", line 1357, in decoration_helper
    arg = exit_stack.enter_context(patching)
          ^^^^^^^^^^^^^^^^^^^^^^^^^^^^^^^^^^
  File "C:\Program Files\WindowsApps\PythonSoftwareFoundation.Python.3.11_3.11.2544.0_x64__qbz5n2kfra8p0\Lib\contextlib.py", line 517, in enter_context
    result = _enter(cm)
             ^^^^^^^^^^
  File "C:\Program Files\WindowsApps\PythonSoftwareFoundation.Python.3.11_3.11.2544.0_x64__qbz5n2kfra8p0\Lib\unittest\mock.py", line 1446, in __enter__
    original, local = self.get_original()
                      ^^^^^^^^^^^^^^^^^^^
  File "C:\Program Files\WindowsApps\PythonSoftwareFoundation.Python.3.11_3.11.2544.0_x64__qbz5n2kfra8p0\Lib\unittest\mock.py", line 1419, in get_original
    raise AttributeError(
AttributeError: <module 'app2' from 'C:\\Users\\Omistaja\\PycharmProjects\\MLEngine3\\backend\\app2.py'> does not have the attribute 'register_user'
]]></error>
	</testcase>
	<testcase classname="TestRoutes.TestUsersBlueprint" name="test_save" time="0.005">
		<error type="AttributeError" message="&lt;module 'app2' from 'C:\\Users\\Omistaja\\PycharmProjects\\MLEngine3\\backend\\app2.py'&gt; does not have the attribute 'save'"><![CDATA[Traceback (most recent call last):
  File "C:\Program Files\WindowsApps\PythonSoftwareFoundation.Python.3.11_3.11.2544.0_x64__qbz5n2kfra8p0\Lib\unittest\mock.py", line 1375, in patched
    with self.decoration_helper(patched,
  File "C:\Program Files\WindowsApps\PythonSoftwareFoundation.Python.3.11_3.11.2544.0_x64__qbz5n2kfra8p0\Lib\contextlib.py", line 137, in __enter__
    return next(self.gen)
           ^^^^^^^^^^^^^^
  File "C:\Program Files\WindowsApps\PythonSoftwareFoundation.Python.3.11_3.11.2544.0_x64__qbz5n2kfra8p0\Lib\unittest\mock.py", line 1357, in decoration_helper
    arg = exit_stack.enter_context(patching)
          ^^^^^^^^^^^^^^^^^^^^^^^^^^^^^^^^^^
  File "C:\Program Files\WindowsApps\PythonSoftwareFoundation.Python.3.11_3.11.2544.0_x64__qbz5n2kfra8p0\Lib\contextlib.py", line 517, in enter_context
    result = _enter(cm)
             ^^^^^^^^^^
  File "C:\Program Files\WindowsApps\PythonSoftwareFoundation.Python.3.11_3.11.2544.0_x64__qbz5n2kfra8p0\Lib\unittest\mock.py", line 1446, in __enter__
    original, local = self.get_original()
                      ^^^^^^^^^^^^^^^^^^^
  File "C:\Program Files\WindowsApps\PythonSoftwareFoundation.Python.3.11_3.11.2544.0_x64__qbz5n2kfra8p0\Lib\unittest\mock.py", line 1419, in get_original
    raise AttributeError(
AttributeError: <module 'app2' from 'C:\\Users\\Omistaja\\PycharmProjects\\MLEngine3\\backend\\app2.py'> does not have the attribute 'save'
]]></error>
	</testcase>
	<system-out><![CDATA[]]></system-out>
	<system-err><![CDATA[]]></system-err>
</testsuite>
