<?xml version="1.0" ?>
<testsuite name="TestRoutes.TestUsersBlueprint-20240410223017" tests="5" time="0.036" failures="0" errors="1">
	<testcase classname="TestRoutes.TestUsersBlueprint" name="test_login" time="0.022"/>
	<testcase classname="TestRoutes.TestUsersBlueprint" name="test_login_fail" time="0.002"/>
	<testcase classname="TestRoutes.TestUsersBlueprint" name="test_prediction" time="0.004"/>
	<testcase classname="TestRoutes.TestUsersBlueprint" name="test_save" time="0.001"/>
	<testcase classname="TestRoutes.TestUsersBlueprint" name="test_register" time="0.008">
		<error type="JSONDecodeError" message="Expecting value: line 1 column 1 (char 0)"><![CDATA[Traceback (most recent call last):
  File "C:\Program Files\WindowsApps\PythonSoftwareFoundation.Python.3.11_3.11.2544.0_x64__qbz5n2kfra8p0\Lib\unittest\mock.py", line 1378, in patched
    return func(*newargs, **newkeywargs)
           ^^^^^^^^^^^^^^^^^^^^^^^^^^^^^
  File "C:\Users\Omistaja\PycharmProjects\MLEngine3\backend\tests\TestRoutes.py", line 19, in test_register
    data = json.loads(response.data.decode())
           ^^^^^^^^^^^^^^^^^^^^^^^^^^^^^^^^^^
  File "C:\Program Files\WindowsApps\PythonSoftwareFoundation.Python.3.11_3.11.2544.0_x64__qbz5n2kfra8p0\Lib\json\__init__.py", line 346, in loads
    return _default_decoder.decode(s)
           ^^^^^^^^^^^^^^^^^^^^^^^^^^
  File "C:\Program Files\WindowsApps\PythonSoftwareFoundation.Python.3.11_3.11.2544.0_x64__qbz5n2kfra8p0\Lib\json\decoder.py", line 337, in decode
    obj, end = self.raw_decode(s, idx=_w(s, 0).end())
               ^^^^^^^^^^^^^^^^^^^^^^^^^^^^^^^^^^^^^^
  File "C:\Program Files\WindowsApps\PythonSoftwareFoundation.Python.3.11_3.11.2544.0_x64__qbz5n2kfra8p0\Lib\json\decoder.py", line 355, in raw_decode
    raise JSONDecodeError("Expecting value", s, err.value) from None
json.decoder.JSONDecodeError: Expecting value: line 1 column 1 (char 0)
]]></error>
	</testcase>
	<system-out><![CDATA[]]></system-out>
	<system-err><![CDATA[[2024-04-10 22:30:17,418] ERROR in app: Exception on /register [POST]
Traceback (most recent call last):
  File "C:\Users\Omistaja\PycharmProjects\MLEngine3\.venv\Lib\site-packages\flask\app.py", line 1463, in wsgi_app
    response = self.full_dispatch_request()
               ^^^^^^^^^^^^^^^^^^^^^^^^^^^^
  File "C:\Users\Omistaja\PycharmProjects\MLEngine3\.venv\Lib\site-packages\flask\app.py", line 872, in full_dispatch_request
    rv = self.handle_user_exception(e)
         ^^^^^^^^^^^^^^^^^^^^^^^^^^^^^
  File "C:\Users\Omistaja\PycharmProjects\MLEngine3\.venv\Lib\site-packages\flask_cors\extension.py", line 176, in wrapped_function
    return cors_after_request(app.make_response(f(*args, **kwargs)))
                                                ^^^^^^^^^^^^^^^^^^
  File "C:\Users\Omistaja\PycharmProjects\MLEngine3\.venv\Lib\site-packages\flask\app.py", line 870, in full_dispatch_request
    rv = self.dispatch_request()
         ^^^^^^^^^^^^^^^^^^^^^^^
  File "C:\Users\Omistaja\PycharmProjects\MLEngine3\.venv\Lib\site-packages\flask\app.py", line 855, in dispatch_request
    return self.ensure_sync(self.view_functions[rule.endpoint])(**view_args)  # type: ignore[no-any-return]
           ^^^^^^^^^^^^^^^^^^^^^^^^^^^^^^^^^^^^^^^^^^^^^^^^^^^^^^^^^^^^^^^^^
  File "C:\Users\Omistaja\PycharmProjects\MLEngine3\backend\routes.py", line 9, in register
    new_user = register_user(user_data)
               ^^^^^^^^^^^^^^^^^^^^^^^^
  File "C:\Users\Omistaja\PycharmProjects\MLEngine3\backend\services.py", line 30, in register_user
    firstName_en=user_data['firstName_en'],
                 ~~~~~~~~~^^^^^^^^^^^^^^^^
KeyError: 'firstName_en'
]]></system-err>
</testsuite>
