<?xml version="1.0" ?>
<testsuite name="TestRoutes.TestUsersBlueprint-20240410221935" tests="4" time="0.115" failures="0" errors="4">
	<testcase classname="TestRoutes.TestUsersBlueprint" name="test_login" time="0.057">
		<error type="JSONDecodeError" message="Expecting value: line 1 column 1 (char 0)"><![CDATA[Traceback (most recent call last):
  File "C:\Program Files\WindowsApps\PythonSoftwareFoundation.Python.3.11_3.11.2544.0_x64__qbz5n2kfra8p0\Lib\unittest\mock.py", line 1378, in patched
    return func(*newargs, **newkeywargs)
           ^^^^^^^^^^^^^^^^^^^^^^^^^^^^^
  File "C:\Users\Omistaja\PycharmProjects\MLEngine3\backend\tests\TestRoutes.py", line 29, in test_login
    data = json.loads(response.data.decode())
           ^^^^^^^^^^^^^^^^^^^^^^^^^^^^^^^^^^
  File "C:\Program Files\WindowsApps\PythonSoftwareFoundation.Python.3.11_3.11.2544.0_x64__qbz5n2kfra8p0\Lib\json\__init__.py", line 346, in loads
    return _default_decoder.decode(s)
           ^^^^^^^^^^^^^^^^^^^^^^^^^^
  File "C:\Program Files\WindowsApps\PythonSoftwareFoundation.Python.3.11_3.11.2544.0_x64__qbz5n2kfra8p0\Lib\json\decoder.py", line 337, in decode
    obj, end = self.raw_decode(s, idx=_w(s, 0).end())
               ^^^^^^^^^^^^^^^^^^^^^^^^^^^^^^^^^^^^^^
  File "C:\Program Files\WindowsApps\PythonSoftwareFoundation.Python.3.11_3.11.2544.0_x64__qbz5n2kfra8p0\Lib\json\decoder.py", line 355, in raw_decode
    raise JSONDecodeError("Expecting value", s, err.value) from None
json.decoder.JSONDecodeError: Expecting value: line 1 column 1 (char 0)
]]></error>
	</testcase>
	<testcase classname="TestRoutes.TestUsersBlueprint" name="test_login_fail" time="0.015">
		<error type="JSONDecodeError" message="Expecting value: line 1 column 1 (char 0)"><![CDATA[Traceback (most recent call last):
  File "C:\Program Files\WindowsApps\PythonSoftwareFoundation.Python.3.11_3.11.2544.0_x64__qbz5n2kfra8p0\Lib\unittest\mock.py", line 1378, in patched
    return func(*newargs, **newkeywargs)
           ^^^^^^^^^^^^^^^^^^^^^^^^^^^^^
  File "C:\Users\Omistaja\PycharmProjects\MLEngine3\backend\tests\TestRoutes.py", line 39, in test_login_fail
    data = json.loads(response.data.decode())
           ^^^^^^^^^^^^^^^^^^^^^^^^^^^^^^^^^^
  File "C:\Program Files\WindowsApps\PythonSoftwareFoundation.Python.3.11_3.11.2544.0_x64__qbz5n2kfra8p0\Lib\json\__init__.py", line 346, in loads
    return _default_decoder.decode(s)
           ^^^^^^^^^^^^^^^^^^^^^^^^^^
  File "C:\Program Files\WindowsApps\PythonSoftwareFoundation.Python.3.11_3.11.2544.0_x64__qbz5n2kfra8p0\Lib\json\decoder.py", line 337, in decode
    obj, end = self.raw_decode(s, idx=_w(s, 0).end())
               ^^^^^^^^^^^^^^^^^^^^^^^^^^^^^^^^^^^^^^
  File "C:\Program Files\WindowsApps\PythonSoftwareFoundation.Python.3.11_3.11.2544.0_x64__qbz5n2kfra8p0\Lib\json\decoder.py", line 355, in raw_decode
    raise JSONDecodeError("Expecting value", s, err.value) from None
json.decoder.JSONDecodeError: Expecting value: line 1 column 1 (char 0)
]]></error>
	</testcase>
	<testcase classname="TestRoutes.TestUsersBlueprint" name="test_prediction" time="0.027">
		<error type="JSONDecodeError" message="Expecting value: line 1 column 1 (char 0)"><![CDATA[Traceback (most recent call last):
  File "C:\Program Files\WindowsApps\PythonSoftwareFoundation.Python.3.11_3.11.2544.0_x64__qbz5n2kfra8p0\Lib\unittest\mock.py", line 1378, in patched
    return func(*newargs, **newkeywargs)
           ^^^^^^^^^^^^^^^^^^^^^^^^^^^^^
  File "C:\Users\Omistaja\PycharmProjects\MLEngine3\backend\tests\TestRoutes.py", line 49, in test_prediction
    data = json.loads(response.data.decode())
           ^^^^^^^^^^^^^^^^^^^^^^^^^^^^^^^^^^
  File "C:\Program Files\WindowsApps\PythonSoftwareFoundation.Python.3.11_3.11.2544.0_x64__qbz5n2kfra8p0\Lib\json\__init__.py", line 346, in loads
    return _default_decoder.decode(s)
           ^^^^^^^^^^^^^^^^^^^^^^^^^^
  File "C:\Program Files\WindowsApps\PythonSoftwareFoundation.Python.3.11_3.11.2544.0_x64__qbz5n2kfra8p0\Lib\json\decoder.py", line 337, in decode
    obj, end = self.raw_decode(s, idx=_w(s, 0).end())
               ^^^^^^^^^^^^^^^^^^^^^^^^^^^^^^^^^^^^^^
  File "C:\Program Files\WindowsApps\PythonSoftwareFoundation.Python.3.11_3.11.2544.0_x64__qbz5n2kfra8p0\Lib\json\decoder.py", line 355, in raw_decode
    raise JSONDecodeError("Expecting value", s, err.value) from None
json.decoder.JSONDecodeError: Expecting value: line 1 column 1 (char 0)
]]></error>
	</testcase>
	<testcase classname="TestRoutes.TestUsersBlueprint" name="test_save" time="0.017">
		<error type="JSONDecodeError" message="Expecting value: line 1 column 1 (char 0)"><![CDATA[Traceback (most recent call last):
  File "C:\Program Files\WindowsApps\PythonSoftwareFoundation.Python.3.11_3.11.2544.0_x64__qbz5n2kfra8p0\Lib\unittest\mock.py", line 1378, in patched
    return func(*newargs, **newkeywargs)
           ^^^^^^^^^^^^^^^^^^^^^^^^^^^^^
  File "C:\Users\Omistaja\PycharmProjects\MLEngine3\backend\tests\TestRoutes.py", line 59, in test_save
    data = json.loads(response.data.decode())
           ^^^^^^^^^^^^^^^^^^^^^^^^^^^^^^^^^^
  File "C:\Program Files\WindowsApps\PythonSoftwareFoundation.Python.3.11_3.11.2544.0_x64__qbz5n2kfra8p0\Lib\json\__init__.py", line 346, in loads
    return _default_decoder.decode(s)
           ^^^^^^^^^^^^^^^^^^^^^^^^^^
  File "C:\Program Files\WindowsApps\PythonSoftwareFoundation.Python.3.11_3.11.2544.0_x64__qbz5n2kfra8p0\Lib\json\decoder.py", line 337, in decode
    obj, end = self.raw_decode(s, idx=_w(s, 0).end())
               ^^^^^^^^^^^^^^^^^^^^^^^^^^^^^^^^^^^^^^
  File "C:\Program Files\WindowsApps\PythonSoftwareFoundation.Python.3.11_3.11.2544.0_x64__qbz5n2kfra8p0\Lib\json\decoder.py", line 355, in raw_decode
    raise JSONDecodeError("Expecting value", s, err.value) from None
json.decoder.JSONDecodeError: Expecting value: line 1 column 1 (char 0)
]]></error>
	</testcase>
	<system-out><![CDATA[]]></system-out>
	<system-err><![CDATA[[2024-04-10 22:19:35,085] ERROR in app: Exception on /login [POST]
Traceback (most recent call last):
  File "C:\Users\Omistaja\PycharmProjects\MLEngine3\.venv\Lib\site-packages\flask\app.py", line 1463, in wsgi_app
    response = self.full_dispatch_request()
               ^^^^^^^^^^^^^^^^^^^^^^^^^^^^
  File "C:\Users\Omistaja\PycharmProjects\MLEngine3\.venv\Lib\site-packages\flask\app.py", line 872, in full_dispatch_request
    rv = self.handle_user_exception(e)
         ^^^^^^^^^^^^^^^^^^^^^^^^^^^^^
  File "C:\Users\Omistaja\PycharmProjects\MLEngine3\.venv\Lib\site-packages\flask\app.py", line 870, in full_dispatch_request
    rv = self.dispatch_request()
         ^^^^^^^^^^^^^^^^^^^^^^^
  File "C:\Users\Omistaja\PycharmProjects\MLEngine3\.venv\Lib\site-packages\flask\app.py", line 855, in dispatch_request
    return self.ensure_sync(self.view_functions[rule.endpoint])(**view_args)  # type: ignore[no-any-return]
           ^^^^^^^^^^^^^^^^^^^^^^^^^^^^^^^^^^^^^^^^^^^^^^^^^^^^^^^^^^^^^^^^^
  File "C:\Users\Omistaja\PycharmProjects\MLEngine3\backend\routes.py", line 15, in login
    user = login_user(credentials)
           ^^^^^^^^^^^^^^^^^^^^^^^
  File "C:\Users\Omistaja\PycharmProjects\MLEngine3\backend\services.py", line 49, in login_user
    user = User.query.filter_by(email=email, password=password).first()
           ^^^^^^^^^^^^^^^^^^^^^^^^^^^^^^^^^^^^^^^^^^^^^^^^^^^^^^^^^^^^
  File "C:\Users\Omistaja\PycharmProjects\MLEngine3\.venv\Lib\site-packages\sqlalchemy\orm\query.py", line 2728, in first
    return self.limit(1)._iter().first()  # type: ignore
           ^^^^^^^^^^^^^^^^^^^^^
  File "C:\Users\Omistaja\PycharmProjects\MLEngine3\.venv\Lib\site-packages\sqlalchemy\orm\query.py", line 2827, in _iter
    result: Union[ScalarResult[_T], Result[_T]] = self.session.execute(
                                                  ^^^^^^^^^^^^^^^^^^^^^
  File "C:\Users\Omistaja\PycharmProjects\MLEngine3\.venv\Lib\site-packages\sqlalchemy\orm\session.py", line 2306, in execute
    return self._execute_internal(
           ^^^^^^^^^^^^^^^^^^^^^^^
  File "C:\Users\Omistaja\PycharmProjects\MLEngine3\.venv\Lib\site-packages\sqlalchemy\orm\session.py", line 2179, in _execute_internal
    bind = self.get_bind(**bind_arguments)
           ^^^^^^^^^^^^^^^^^^^^^^^^^^^^^^^
  File "C:\Users\Omistaja\PycharmProjects\MLEngine3\.venv\Lib\site-packages\flask_sqlalchemy\session.py", line 53, in get_bind
    engines = self._db.engines
              ^^^^^^^^^^^^^^^^
  File "C:\Users\Omistaja\PycharmProjects\MLEngine3\.venv\Lib\site-packages\flask_sqlalchemy\extension.py", line 690, in engines
    raise RuntimeError(
RuntimeError: The current Flask app is not registered with this 'SQLAlchemy' instance. Did you forget to call 'init_app', or did you create multiple 'SQLAlchemy' instances?
[2024-04-10 22:19:35,109] ERROR in app: Exception on /login [POST]
Traceback (most recent call last):
  File "C:\Users\Omistaja\PycharmProjects\MLEngine3\.venv\Lib\site-packages\flask\app.py", line 1463, in wsgi_app
    response = self.full_dispatch_request()
               ^^^^^^^^^^^^^^^^^^^^^^^^^^^^
  File "C:\Users\Omistaja\PycharmProjects\MLEngine3\.venv\Lib\site-packages\flask\app.py", line 872, in full_dispatch_request
    rv = self.handle_user_exception(e)
         ^^^^^^^^^^^^^^^^^^^^^^^^^^^^^
  File "C:\Users\Omistaja\PycharmProjects\MLEngine3\.venv\Lib\site-packages\flask\app.py", line 870, in full_dispatch_request
    rv = self.dispatch_request()
         ^^^^^^^^^^^^^^^^^^^^^^^
  File "C:\Users\Omistaja\PycharmProjects\MLEngine3\.venv\Lib\site-packages\flask\app.py", line 855, in dispatch_request
    return self.ensure_sync(self.view_functions[rule.endpoint])(**view_args)  # type: ignore[no-any-return]
           ^^^^^^^^^^^^^^^^^^^^^^^^^^^^^^^^^^^^^^^^^^^^^^^^^^^^^^^^^^^^^^^^^
  File "C:\Users\Omistaja\PycharmProjects\MLEngine3\backend\routes.py", line 15, in login
    user = login_user(credentials)
           ^^^^^^^^^^^^^^^^^^^^^^^
  File "C:\Users\Omistaja\PycharmProjects\MLEngine3\backend\services.py", line 49, in login_user
    user = User.query.filter_by(email=email, password=password).first()
           ^^^^^^^^^^^^^^^^^^^^^^^^^^^^^^^^^^^^^^^^^^^^^^^^^^^^^^^^^^^^
  File "C:\Users\Omistaja\PycharmProjects\MLEngine3\.venv\Lib\site-packages\sqlalchemy\orm\query.py", line 2728, in first
    return self.limit(1)._iter().first()  # type: ignore
           ^^^^^^^^^^^^^^^^^^^^^
  File "C:\Users\Omistaja\PycharmProjects\MLEngine3\.venv\Lib\site-packages\sqlalchemy\orm\query.py", line 2827, in _iter
    result: Union[ScalarResult[_T], Result[_T]] = self.session.execute(
                                                  ^^^^^^^^^^^^^^^^^^^^^
  File "C:\Users\Omistaja\PycharmProjects\MLEngine3\.venv\Lib\site-packages\sqlalchemy\orm\session.py", line 2306, in execute
    return self._execute_internal(
           ^^^^^^^^^^^^^^^^^^^^^^^
  File "C:\Users\Omistaja\PycharmProjects\MLEngine3\.venv\Lib\site-packages\sqlalchemy\orm\session.py", line 2179, in _execute_internal
    bind = self.get_bind(**bind_arguments)
           ^^^^^^^^^^^^^^^^^^^^^^^^^^^^^^^
  File "C:\Users\Omistaja\PycharmProjects\MLEngine3\.venv\Lib\site-packages\flask_sqlalchemy\session.py", line 53, in get_bind
    engines = self._db.engines
              ^^^^^^^^^^^^^^^^
  File "C:\Users\Omistaja\PycharmProjects\MLEngine3\.venv\Lib\site-packages\flask_sqlalchemy\extension.py", line 690, in engines
    raise RuntimeError(
RuntimeError: The current Flask app is not registered with this 'SQLAlchemy' instance. Did you forget to call 'init_app', or did you create multiple 'SQLAlchemy' instances?
[2024-04-10 22:19:35,130] ERROR in app: Exception on /predict [POST]
Traceback (most recent call last):
  File "C:\Users\Omistaja\PycharmProjects\MLEngine3\.venv\Lib\site-packages\flask\app.py", line 1463, in wsgi_app
    response = self.full_dispatch_request()
               ^^^^^^^^^^^^^^^^^^^^^^^^^^^^
  File "C:\Users\Omistaja\PycharmProjects\MLEngine3\.venv\Lib\site-packages\flask\app.py", line 872, in full_dispatch_request
    rv = self.handle_user_exception(e)
         ^^^^^^^^^^^^^^^^^^^^^^^^^^^^^
  File "C:\Users\Omistaja\PycharmProjects\MLEngine3\.venv\Lib\site-packages\flask\app.py", line 870, in full_dispatch_request
    rv = self.dispatch_request()
         ^^^^^^^^^^^^^^^^^^^^^^^
  File "C:\Users\Omistaja\PycharmProjects\MLEngine3\.venv\Lib\site-packages\flask\app.py", line 855, in dispatch_request
    return self.ensure_sync(self.view_functions[rule.endpoint])(**view_args)  # type: ignore[no-any-return]
           ^^^^^^^^^^^^^^^^^^^^^^^^^^^^^^^^^^^^^^^^^^^^^^^^^^^^^^^^^^^^^^^^^
  File "C:\Users\Omistaja\PycharmProjects\MLEngine3\backend\routes.py", line 24, in prediction
    user_prediction = predict(user_data)
                      ^^^^^^^^^^^^^^^^^^
  File "C:\Users\Omistaja\PycharmProjects\MLEngine3\backend\services.py", line 73, in predict
    input_data_scaled = scaler.transform([data])  # Scale the input data
                        ^^^^^^^^^^^^^^^^^^^^^^^^
  File "C:\Users\Omistaja\PycharmProjects\MLEngine3\.venv\Lib\site-packages\sklearn\utils\_set_output.py", line 295, in wrapped
    data_to_wrap = f(self, X, *args, **kwargs)
                   ^^^^^^^^^^^^^^^^^^^^^^^^^^^
  File "C:\Users\Omistaja\PycharmProjects\MLEngine3\.venv\Lib\site-packages\sklearn\preprocessing\_data.py", line 1043, in transform
    X = self._validate_data(
        ^^^^^^^^^^^^^^^^^^^^
  File "C:\Users\Omistaja\PycharmProjects\MLEngine3\.venv\Lib\site-packages\sklearn\base.py", line 633, in _validate_data
    out = check_array(X, input_name="X", **check_params)
          ^^^^^^^^^^^^^^^^^^^^^^^^^^^^^^^^^^^^^^^^^^^^^^
  File "C:\Users\Omistaja\PycharmProjects\MLEngine3\.venv\Lib\site-packages\sklearn\utils\validation.py", line 997, in check_array
    array = _asarray_with_order(array, order=order, dtype=dtype, xp=xp)
            ^^^^^^^^^^^^^^^^^^^^^^^^^^^^^^^^^^^^^^^^^^^^^^^^^^^^^^^^^^^
  File "C:\Users\Omistaja\PycharmProjects\MLEngine3\.venv\Lib\site-packages\sklearn\utils\_array_api.py", line 521, in _asarray_with_order
    array = numpy.asarray(array, order=order, dtype=dtype)
            ^^^^^^^^^^^^^^^^^^^^^^^^^^^^^^^^^^^^^^^^^^^^^^
ValueError: could not convert string to float: 'test'
[2024-04-10 22:19:35,152] ERROR in app: Exception on /save [POST]
Traceback (most recent call last):
  File "C:\Users\Omistaja\PycharmProjects\MLEngine3\.venv\Lib\site-packages\flask\app.py", line 1463, in wsgi_app
    response = self.full_dispatch_request()
               ^^^^^^^^^^^^^^^^^^^^^^^^^^^^
  File "C:\Users\Omistaja\PycharmProjects\MLEngine3\.venv\Lib\site-packages\flask\app.py", line 872, in full_dispatch_request
    rv = self.handle_user_exception(e)
         ^^^^^^^^^^^^^^^^^^^^^^^^^^^^^
  File "C:\Users\Omistaja\PycharmProjects\MLEngine3\.venv\Lib\site-packages\flask\app.py", line 870, in full_dispatch_request
    rv = self.dispatch_request()
         ^^^^^^^^^^^^^^^^^^^^^^^
  File "C:\Users\Omistaja\PycharmProjects\MLEngine3\.venv\Lib\site-packages\flask\app.py", line 855, in dispatch_request
    return self.ensure_sync(self.view_functions[rule.endpoint])(**view_args)  # type: ignore[no-any-return]
           ^^^^^^^^^^^^^^^^^^^^^^^^^^^^^^^^^^^^^^^^^^^^^^^^^^^^^^^^^^^^^^^^^
  File "C:\Users\Omistaja\PycharmProjects\MLEngine3\backend\routes.py", line 29, in persist
    save_user = save(user_data)
                ^^^^^^^^^^^^^^^
  File "C:\Users\Omistaja\PycharmProjects\MLEngine3\backend\services.py", line 112, in save
    userID=user_data['userID']
           ~~~~~~~~~^^^^^^^^^^
KeyError: 'userID'
]]></system-err>
</testsuite>
