<?xml version="1.0" ?>
<testsuite name="TestRoutes.TestUsersBlueprint-20240411095639" tests="5" time="0.057" failures="0" errors="1">
	<testcase classname="TestRoutes.TestUsersBlueprint" name="test_login" time="0.017"/>
	<testcase classname="TestRoutes.TestUsersBlueprint" name="test_login_fail" time="0.002"/>
	<testcase classname="TestRoutes.TestUsersBlueprint" name="test_prediction" time="0.002"/>
	<testcase classname="TestRoutes.TestUsersBlueprint" name="test_save" time="0.001"/>
	<testcase classname="TestRoutes.TestUsersBlueprint" name="test_register" time="0.035">
		<error type="AssertionError" message="Expected 'register_user' to be called once. Called 0 times."><![CDATA[Traceback (most recent call last):
  File "C:\Program Files\WindowsApps\PythonSoftwareFoundation.Python.3.11_3.11.2544.0_x64__qbz5n2kfra8p0\Lib\unittest\mock.py", line 1378, in patched
    return func(*newargs, **newkeywargs)
           ^^^^^^^^^^^^^^^^^^^^^^^^^^^^^
  File "C:\Users\Omistaja\PycharmProjects\MLEngine3\backend\tests\TestRoutes.py", line 24, in test_register
    mock_register.assert_called_once_with()
  File "C:\Program Files\WindowsApps\PythonSoftwareFoundation.Python.3.11_3.11.2544.0_x64__qbz5n2kfra8p0\Lib\unittest\mock.py", line 950, in assert_called_once_with
    raise AssertionError(msg)
AssertionError: Expected 'register_user' to be called once. Called 0 times.
]]></error>
	</testcase>
	<system-out><![CDATA[]]></system-out>
	<system-err><![CDATA[]]></system-err>
</testsuite>
